Workbook

Sheet Итог
A1: Камчатскэнерго 32616346943 — арматура среднего и низкого давления (Лот 0200-РЕМ ПРОД-2027-КамчЭн)
A2: Конкурс в эл. форме, 223-ФЗ, Росэлторг (секция РусГидро). Подача до 29.10.2026. НМЦК с НДС. Наша цена = цена договора (УСН).
A3: Показатель | B3: Значение | C3: Комментарий
A4: НМЦК, ₽ | B4: 101102908 | C4: весь лот, 315 позиций, 3 383 ед., 4 грузополучателя
A5: Позиций с ценой | B5: =COUNT(Позиции!J3:J317) | C5: из 315; пустые — ищем, можно вписать вручную на листе «Позиции»
A6: Себестоимость по найденным позициям (после торга −10%, с доставкой), ₽ | B6: =Позиции!O318 | C6: сумма столбца O листа «Позиции»
A7: Оценка себестоимости всего лота, ₽ | B7: =IF(COUNT(Позиции!J3:J317)=0,65661745.0,B6/MAX(B5,1)*315) | C7: пока цен нет — оценка по истории лотов (60% НМЦК + 5 млн доставка); по мере заполнения — экстраполяция по найденным
A8: Маржа при НМЦК | B8: =1-B7/B4
A9: Ожидаемое снижение на конкурсе | B9: 0.15 | C9: история: −7% … −23% (2025–2026), большинство заявок отклоняют
A10: Цена заявки, ₽ | B10: =B4*(1-B9)
A11: Прибыль до налога, ₽ | B11: =B10-B7-0.008*B10-B7*0.2*120/365 | C11: 0,8% ЭП/банк, деньги 20% годовых на 120 дней
A12: Прибыль после УСН 15%, ₽ | B12: =B11-0.15*MAX(B11,0)
A13: Маржа к цене заявки | B13: =B12/B10
A15: Сценарии снижения | B15: Прибыль после УСН, ₽
A16: −0% | B16: =(B4*(1-0)-B7-0.008*B4*(1-0)-B7*0.2*120/365)*IF(B4*(1-0)-B7-0.008*B4*(1-0)-B7*0.2*120/365>0,0.85,1)
A17: −7% | B17: =(B4*(1-0.07)-B7-0.008*B4*(1-0.07)-B7*0.2*120/365)*IF(B4*(1-0.07)-B7-0.008*B4*(1-0.07)-B7*0.2*120/365>0,0.85,1)
A18: −15% | B18: =(B4*(1-0.15)-B7-0.008*B4*(1-0.15)-B7*0.2*120/365)*IF(B4*(1-0.15)-B7-0.008*B4*(1-0.15)-B7*0.2*120/365>0,0.85,1)
A19: −23% | B19: =(B4*(1-0.23)-B7-0.008*B4*(1-0.23)-B7*0.2*120/365)*IF(B4*(1-0.23)-B7-0.008*B4*(1-0.23)-B7*0.2*120/365>0,0.85,1)
A20: −30% | B20: =(B4*(1-0.3)-B7-0.008*B4*(1-0.3)-B7*0.2*120/365)*IF(B4*(1-0.3)-B7-0.008*B4*(1-0.3)-B7*0.2*120/365>0,0.85,1)
A22: Условия
A23: Поставка | B23: в течение 120 календарных дней с подписания договора; Петропавловск-Камчатский (ул. Пограничная 75А, ул. Степная 50, пр. Победы 24) и Елизовский р-н, пос. Светлый
A24: Обеспечение заявки | B24: 1 005 499,42 ₽ (БГ или деньги)
A25: Аванс | B25: предусмотрен; обеспечение возврата аванса — 100% суммы аванса (БГ); размер — в проекте договора
A26: Гарантия | B26: по заводу, не менее 12 мес.; изготовление — год поставки или предыдущий
A27: Нацрежим | B27: ПП 1875 — ограничение + преимущество: по каждой позиции номер записи в реестре Минпромторга/ЕАЭС
A28: Документы | B28: сертификаты/декларации ТР ТС 032/2013 и 010/2011 со схемами 1с/5Д и протоколами испытаний; техпредложение по Прил. 1
A29: Аккредитация | B29: аккредитация в РусГидро (Прил. 10)
A30: Подача на часть лота | B30: нельзя — лот неделимый
A31: Эквиваленты | B31: допускаются, марка носит описательный характер; нужно обоснование эквивалентности
A33: История лотов Камчатскэнерго
A34: 13000-РЕМ ПРОД-2026-КамчЭн | B34: НМЦК 119 527 144 ₽ → победитель 92043800; снижение 0.23 | C34: 4 из 6 (п.4.9.6 а — состав/оформление заявки), включая 47.8 и 89.999 млн
A35: 25900-РЕМ ПРОД-2025-КамчЭн | B35: НМЦК 85 866 140 ₽ → победитель 79900000; снижение 0.07 | C35: 0 из 3
A36: 1000-РЕМ ПРОД-2026-КамчЭн (арматура среднего давления) | B36: НМЦК 52 886 220 ₽ → победитель 52100110; снижение 0.015 | C36: 9 из 10 — допущена только заявка 52.1 млн
A37: 0100-РЕМ ПРОД-2027-КамчЭн (арматура высокого давления) | B37: НМЦК 180 965 509 ₽ → победитель 157097600; снижение 0.132 | C37: 0 из 2

Sheet Позиции
A1: Камчатскэнерго 32616346943 — позиции, количества, себестоимость (заполненные цены — рынок 2026 с НДС; пустые — ещё ищем, можно вписать вручную)
A2: Таблица | B2: № | C2: Позиция | D2: Кол-во | E2: Ед. | F2: DN | G2: PN, МПа | H2: Материал корпуса | I2: Привод | J2: Цена за ед. (рынок), ₽ | K2: Цена после торга −10%, ₽ | L2: Вес ед., кг | M2: Сумма закупки, ₽ | N2: Доставка, ₽ | O2: Себестоимость позиции, ₽ | P2: Поставщик | Q2: Тип цены / подтверждение 2026 | R2: Аналог / реестр МПТ | S2: Ссылка
A3: 1.1 | B3: 1 | C3: Клапан предохранительный 17лс17нж Ду 200-300 Ру 16-6 полноподъемный пружинный фланцевый | D3: 1 | E3: шт | F3: 200 | G3: 1.6 | H3: Корпус — сталь 20ГЛ ГОСТ 977-88; Крышка | I3: автоматическое/ручное | K3: =IF(J3="","",J3*(1-0.1)) | M3: =IF(J3="","",K3*D3) | N3: =IF(L3="","",L3*D3*55) | O3: =IF(M3="","",M3+N(N3))
A4: 1.1 | B4: 2 | C4: Клапан запорный 15нж65нж Ду 200 Ру 16 | D4: 4 | E4: шт | F4: 200 | G4: 1.6 | H4: 12Х18Н10Т | I4: Ручное | K4: =IF(J4="","",J4*(1-0.1)) | M4: =IF(J4="","",K4*D4) | N4: =IF(L4="","",L4*D4*55) | O4: =IF(M4="","",M4+N(N4))
A5: 1.1 | B5: 3 | C5: Клапан запорный15нж65нж Ду 50 Ру 16 | D5: 3 | E5: шт | F5: 50 | G5: 1.6 | H5: 12Х18Н10Т | I5: Ручное | K5: =IF(J5="","",J5*(1-0.1)) | M5: =IF(J5="","",K5*D5) | N5: =IF(L5="","",L5*D5*55) | O5: =IF(M5="","",M5+N(N5))
A6: 1.1 | B6: 4 | C6: Клапан запорный15с52нж11 Ду 32 Ру 63 под приварку | D6: 12 | E6: шт | F6: 32 | G6: 6.3 | H6: Сталь 20 | I6: ручное | K6: =IF(J6="","",J6*(1-0.1)) | M6: =IF(J6="","",K6*D6) | N6: =IF(L6="","",L6*D6*55) | O6: =IF(M6="","",M6+N(N6))
A7: 1.1 | B7: 5 | C7: Задвижка 30нж41нж Ду 150 Ру 16 1исп. САЗ | D7: 1 | E7: шт | F7: 150 | G7: 1.6 | H7: сталь 12Х18Н9ТЛ | I7: ручной (маховик) | K7: =IF(J7="","",J7*(1-0.1)) | M7: =IF(J7="","",K7*D7) | N7: =IF(L7="","",L7*D7*55) | O7: =IF(M7="","",M7+N(N7))
A8: 1.1 | B8: 6 | C8: Задвижка 30нж947нж Ду 1000 Ру 4 | D8: 1 | E8: шт | F8: 1000 | G8: 0.4 | H8: Ст.12Х18Н10Т | I8: Под привод , тип присоединения | K8: =IF(J8="","",J8*(1-0.1)) | M8: =IF(J8="","",K8*D8) | N8: =IF(L8="","",L8*D8*55) | O8: =IF(M8="","",M8+N(N8))
A9: 1.1 | B9: 7 | C9: Задвижка 30с41нж Ду 50 Ру 16 | D9: 10 | E9: шт | F9: 50 | G9: 1.6 | H9: Сталь 25 Л | I9: Ручное | K9: =IF(J9="","",J9*(1-0.1)) | M9: =IF(J9="","",K9*D9) | N9: =IF(L9="","",L9*D9*55) | O9: =IF(M9="","",M9+N(N9))
A10: 1.1 | B10: 8 | C10: Задвижка 30с41нж Ду 100 Ру 16 | D10: 7 | E10: шт | F10: 100 | G10: 1.6 | H10: сталь 25Л | I10: ручной (маховик) | K10: =IF(J10="","",J10*(1-0.1)) | M10: =IF(J10="","",K10*D10) | N10: =IF(L10="","",L10*D10*55) | O10: =IF(M10="","",M10+N(N10))
A11: 1.1 | B11: 9 | C11: Задвижка 30с41нж Ду 150 Ру 16 | D11: 10 | E11: шт | F11: 150 | G11: 1.6 | H11: сталь 25Л | I11: ручной (маховик) | K11: =IF(J11="","",J11*(1-0.1)) | M11: =IF(J11="","",K11*D11) | N11: =IF(L11="","",L11*D11*55) | O11: =IF(M11="","",M11+N(N11))
A12: 1.1 | B12: 10 | C12: Задвижка клиновая фланцевая 30с41нж Ду 300 Ру 16 с КОФ | D12: 2 | E12: шт | F12: 300 | G12: 1.6 | H12: сталь 25Л | I12: Ручное | K12: =IF(J12="","",J12*(1-0.1)) | M12: =IF(J12="","",K12*D12) | N12: =IF(L12="","",L12*D12*55) | O12: =IF(M12="","",M12+N(N12))
A13: 1.1 | B13: 11 | C13: Задвижка 30С576НЖ Ду 300 Ру 63 с редуктором РК-Г-1М, в комплекте с крепежом и ответными фланцами. | D13: 2 | E13: шт | F13: 300 | G13: 6.3 | H13: Сталь 25Л | I13: редуктор РК-Г1 | K13: =IF(J13="","",J13*(1-0.1)) | M13: =IF(J13="","",K13*D13) | N13: =IF(L13="","",L13*D13*55) | O13: =IF(M13="","",M13+N(N13))
A14: 1.1 | B14: 12 | C14: Задвижка клиновая фланцевая 30с941нж Ду 500 Ру 16 с КОФ под электропривод Bernard ST-30 | D14: 1 | E14: шт | F14: 500 | G14: 1,6 МПа | H14: сталь 25Л | I14: под электропривод | K14: =IF(J14="","",J14*(1-0.1)) | M14: =IF(J14="","",K14*D14) | N14: =IF(L14="","",L14*D14*55) | O14: =IF(M14="","",M14+N(N14))
A15: 1.1 | B15: 13 | C15: Задвижка 30с964нж Ду 300 Ру 25 | D15: 1 | E15: шт | F15: 300 | G15: 2.5 | H15: Сталь 25Л | I15: Под привод, ручное | K15: =IF(J15="","",J15*(1-0.1)) | M15: =IF(J15="","",K15*D15) | N15: =IF(L15="","",L15*D15*55) | O15: =IF(M15="","",M15+N(N15))
A16: 1.1 | B16: 14 | C16: Кран шаровой 11б27п1 Ду 15 Ру 16 | D16: 35 | E16: шт | F16: 15 | G16: 1.6 | H16: латунь HPb58-2A | I16: Ручное | K16: =IF(J16="","",J16*(1-0.1)) | M16: =IF(J16="","",K16*D16) | N16: =IF(L16="","",L16*D16*55) | O16: =IF(M16="","",M16+N(N16))
A17: 1.1 | B17: 15 | C17: Кран шаровой 11б27п1 Ду 20 Ру 16 | D17: 35 | E17: шт | F17: 20 | G17: 1.6 | H17: латунь HPb58-2A | I17: Ручное | K17: =IF(J17="","",J17*(1-0.1)) | M17: =IF(J17="","",K17*D17) | N17: =IF(L17="","",L17*D17*55) | O17: =IF(M17="","",M17+N(N17))
A18: 1.1 | B18: 16 | C18: Кран шаровой 11б27п1 Ду 25 Ру 16 | D18: 20 | E18: шт | F18: 25 | G18: 1.6 | H18: латунь HPb58-2A | I18: Ручное | K18: =IF(J18="","",J18*(1-0.1)) | M18: =IF(J18="","",K18*D18) | N18: =IF(L18="","",L18*D18*55) | O18: =IF(M18="","",M18+N(N18))
A19: 1.1 | B19: 17 | C19: Кран шаровой 11б27п1 Ду 32 Ру 16 | D19: 25 | E19: шт | F19: 32 | G19: 1.6 | H19: латунь HPb58-2A | I19: Ручное | K19: =IF(J19="","",J19*(1-0.1)) | M19: =IF(J19="","",K19*D19) | N19: =IF(L19="","",L19*D19*55) | O19: =IF(M19="","",M19+N(N19))
A20: 1.1 | B20: 18 | C20: Кран шаровой 11б27п1 Ду 40 Ру 16 | D20: 8 | E20: шт | F20: 40 | G20: 1.6 | H20: латунь HPb58-2A | I20: Ручное | K20: =IF(J20="","",J20*(1-0.1)) | M20: =IF(J20="","",K20*D20) | N20: =IF(L20="","",L20*D20*55) | O20: =IF(M20="","",M20+N(N20))
A21: 1.1 | B21: 19 | C21: Кран шаровой 11б27п1 Ду 50 Ру 16 | D21: 8 | E21: шт | F21: 50 | G21: 1.6 | H21: латунь HPb58-2A | I21: Ручное | K21: =IF(J21="","",J21*(1-0.1)) | M21: =IF(J21="","",K21*D21) | N21: =IF(L21="","",L21*D21*55) | O21: =IF(M21="","",M21+N(N21))
A22: 1.1 | B22: 20 | C22: Кран шаровой 11с67п Ду 150 Ру 25 цельносварной под приварку | D22: 2 | E22: шт | F22: 150 | G22: 2.5 | H22: Сталь 20 | I22: Ручное | K22: =IF(J22="","",J22*(1-0.1)) | M22: =IF(J22="","",K22*D22) | N22: =IF(L22="","",L22*D22*55) | O22: =IF(M22="","",M22+N(N22))
A23: 1.1 | B23: 21 | C23: Кран шаровой 11с67п Ду 200 Ру 16 ЦУФ.001 КШ укороченный полнопроходной фланцевый с рукояткой | D23: 2 | E23: шт | F23: 200 | G23: 1.6 | H23: Сталь 20 | I23: Ручное | K23: =IF(J23="","",J23*(1-0.1)) | M23: =IF(J23="","",K23*D23) | N23: =IF(L23="","",L23*D23*55) | O23: =IF(M23="","",M23+N(N23))
A24: 1.1 | B24: 22 | C24: Затвор дисковый поворотный межфланцевый Stensel 31070-01 Ду 200 Ру 25 | D24: 3 | E24: шт | F24: 200 | G24: 2.5 | H24: Корпус - нержавеющая сталь | I24: Верхний фланец выполнен по ста | K24: =IF(J24="","",J24*(1-0.1)) | M24: =IF(J24="","",K24*D24) | N24: =IF(L24="","",L24*D24*55) | O24: =IF(M24="","",M24+N(N24))
A25: 1.1 | B25: 23 | C25: Затвор дисковый поворотный межфланцевый ПА954.450.10-05 Ду 450 Ру 10 | D25: 1 | E25: шт | F25: 450 | G25: 1 | H25: Корпус - коррозионностойкая молибденосод | I25: Редуктор DN 450 | K25: =IF(J25="","",J25*(1-0.1)) | M25: =IF(J25="","",K25*D25) | N25: =IF(L25="","",L25*D25*55) | O25: =IF(M25="","",M25+N(N25))
A26: 1.1 | B26: 24 | C26: Электропривод общепромышленный Н-В-02 У2 | D26: 2 | E26: шт | F26: Под задвижку 30с964нж Ду 300 | G26: - | H26: - | I26: Электропривод Н-В-02 У2 | K26: =IF(J26="","",J26*(1-0.1)) | M26: =IF(J26="","",K26*D26) | N26: =IF(L26="","",L26*D26*55) | O26: =IF(M26="","",M26+N(N26))
A27: 1.2 | B27: 1 | C27: Кран шаровой 11с67п Ду 32 Ру 25 цельносварной под приварку | D27: 2 | E27: шт | F27: 32 | G27: 2.5 | H27: сталь 20 | I27: ручной (рукоятка) | K27: =IF(J27="","",J27*(1-0.1)) | M27: =IF(J27="","",K27*D27) | N27: =IF(L27="","",L27*D27*55) | O27: =IF(M27="","",M27+N(N27))
A28: 1.2 | B28: 2 | C28: Кран шаровой 11с67п Ду 100 Ру 25 цельносварной под приварку | D28: 4 | E28: шт | F28: 100 | G28: 2.5 | H28: сталь 20 | I28: ручное | K28: =IF(J28="","",J28*(1-0.1)) | M28: =IF(J28="","",K28*D28) | N28: =IF(L28="","",L28*D28*55) | O28: =IF(M28="","",M28+N(N28))
A29: 1.2 | B29: 3 | C29: Кран шаровой 11с67п Ду 50 Ру 25 полнопрох. с КОФ (КЗШС41нж) | D29: 18 | E29: шт | F29: 50 | G29: 2.5 | H29: сталь 20 | I29: Ручное | K29: =IF(J29="","",J29*(1-0.1)) | M29: =IF(J29="","",K29*D29) | N29: =IF(L29="","",L29*D29*55) | O29: =IF(M29="","",M29+N(N29))
A30: 1.2 | B30: 4 | C30: Кран шаровой 11с67п Ду 80 Ру 25 полнопрох. с КОФ (КЗШС41нж) | D30: 4 | E30: шт | F30: 80 | G30: 2.5 | H30: сталь 20 | I30: Ручное | K30: =IF(J30="","",J30*(1-0.1)) | M30: =IF(J30="","",K30*D30) | N30: =IF(L30="","",L30*D30*55) | O30: =IF(M30="","",M30+N(N30))
A31: 1.2 | B31: 5 | C31: Кран шаровой 11с67п Ду 100 Ру 16 ЦУФ.001 КШ укороченный полнопроходной фланцевый с рукояткой | D31: 2 | E31: шт | F31: 100 | G31: 1.6 | H31: сталь 20 | I31: ручное | K31: =IF(J31="","",J31*(1-0.1)) | M31: =IF(J31="","",K31*D31) | N31: =IF(L31="","",L31*D31*55) | O31: =IF(M31="","",M31+N(N31))
A32: 1.3 | B32: 1 | C32: Клапан регулирующий 25с947нж Ду 50 Ру 25 с ЭИМ | D32: 1 | E32: шт | F32: 50 | G32: 2.5 | H32: Сталь марки 25Л ГОСТ 977-88 | I32: электропривод | K32: =IF(J32="","",J32*(1-0.1)) | M32: =IF(J32="","",K32*D32) | N32: =IF(L32="","",L32*D32*55) | O32: =IF(M32="","",M32+N(N32))
A33: 1.3 | B33: 2 | C33: Клапан регулирующий 25ч945п Ду 15 Ру 16 с ЭИМ | D33: 2 | E33: шт | F33: 15 | G33: 1.6 | H33: чугун СЧ20 | I33: автоматический | K33: =IF(J33="","",J33*(1-0.1)) | M33: =IF(J33="","",K33*D33) | N33: =IF(L33="","",L33*D33*55) | O33: =IF(M33="","",M33+N(N33))
A34: 1.3 | B34: 3 | C34: Клапан регулирующий 25ч945п Ду 25 Ру 16 с ЭИМ | D34: 1 | E34: шт | F34: 25 | G34: 1.6 | H34: чугун СЧ20 | I34: автоматический | K34: =IF(J34="","",J34*(1-0.1)) | M34: =IF(J34="","",K34*D34) | N34: =IF(L34="","",L34*D34*55) | O34: =IF(M34="","",M34+N(N34))
A35: 1.3 | B35: 4 | C35: Клапан регулирующий 25ч945п Ду 50 Ру 16 KV100 с ЭИМ | D35: 2 | E35: шт | F35: 50 | G35: 1.6 | H35: чугун СЧ20 | I35: автоматический | K35: =IF(J35="","",J35*(1-0.1)) | M35: =IF(J35="","",K35*D35) | N35: =IF(L35="","",L35*D35*55) | O35: =IF(M35="","",M35+N(N35))
A36: 1.3 | B36: 5 | C36: Клапан регулирующий 25ч945п Ду 80 Ру 16 с ЭИМ | D36: 8 | E36: шт | F36: 80 | G36: 1.6 | H36: чугун СЧ20 | I36: автоматический | K36: =IF(J36="","",J36*(1-0.1)) | M36: =IF(J36="","",K36*D36) | N36: =IF(L36="","",L36*D36*55) | O36: =IF(M36="","",M36+N(N36))
A37: 1.3 | B37: 6 | C37: Регулирующий клапан Ридан VFG-2R Ду 100, Kvs 125, Ру 16 | D37: 2 | E37: шт | F37: 100 | G37: 1.6 | H37: Углеродистая сталь WCB | K37: =IF(J37="","",J37*(1-0.1)) | M37: =IF(J37="","",K37*D37) | N37: =IF(L37="","",L37*D37*55) | O37: =IF(M37="","",M37+N(N37))
A38: 1.3 | B38: 7 | C38: Регулирующий клапан Ридан VFG-2R Ду 32, Kvs 16, Ру 16 | D38: 4 | E38: шт | F38: 32 | G38: 1.6 | H38: Углеродистая сталь WCB | K38: =IF(J38="","",J38*(1-0.1)) | M38: =IF(J38="","",K38*D38) | N38: =IF(L38="","",L38*D38*55) | O38: =IF(M38="","",M38+N(N38))
A39: 1.3 | B39: 8 | C39: регулирующий клапан Ридан VFG-2R Ду 80, Kvs 80, Ру 16 | D39: 2 | E39: шт | F39: 80 | G39: 1.6 | H39: Углеродистая сталь WCB | K39: =IF(J39="","",J39*(1-0.1)) | M39: =IF(J39="","",K39*D39) | N39: =IF(L39="","",L39*D39*55) | O39: =IF(M39="","",M39+N(N39))
A40: 1.3 | B40: 9 | C40: Регулятор давления РД-НО (Нормально открытый) Ду 25 Ру 16 | D40: 2 | E40: шт | F40: 25 | G40: 1.6 | H40: чугун СЧ20 ГОСТ1412 | I40: автоматически действующая труб | K40: =IF(J40="","",J40*(1-0.1)) | M40: =IF(J40="","",K40*D40) | N40: =IF(L40="","",L40*D40*55) | O40: =IF(M40="","",M40+N(N40))
...

Sheet По таблицам
A1: Таблица | B1: Грузополучатель / статья | C1: Позиций | D1: Единиц | E1: Цен найдено | F1: Себестоимость найденных, ₽
A2: 1.1 | B2: Спец. №1 · Возобновляемая энергетика · ремонт | C2: =COUNTIF(Позиции!A3:A317,"1.1") | D2: =SUMIF(Позиции!A3:A317,"1.1",Позиции!D3:D317) | E2: =COUNTIFS(Позиции!A3:A317,"1.1",Позиции!J3:J317,">0") | F2: =SUMIF(Позиции!A3:A317,"1.1",Позиции!O3:O317)
A3: 1.2 | B3: Спец. №2 · КТЭЦ · ремонт арендованного | C3: =COUNTIF(Позиции!A3:A317,"1.2") | D3: =SUMIF(Позиции!A3:A317,"1.2",Позиции!D3:D317) | E3: =COUNTIFS(Позиции!A3:A317,"1.2",Позиции!J3:J317,">0") | F3: =SUMIF(Позиции!A3:A317,"1.2",Позиции!O3:O317)
A4: 1.3 | B4: Спец. №2 · КТЭЦ · ремонт | C4: =COUNTIF(Позиции!A3:A317,"1.3") | D4: =SUMIF(Позиции!A3:A317,"1.3",Позиции!D3:D317) | E4: =COUNTIFS(Позиции!A3:A317,"1.3",Позиции!J3:J317,">0") | F4: =SUMIF(Позиции!A3:A317,"1.3",Позиции!O3:O317)
A5: 1.4 | B5: Спец. №2 · КТЭЦ · эксплуатация | C5: =COUNTIF(Позиции!A3:A317,"1.4") | D5: =SUMIF(Позиции!A3:A317,"1.4",Позиции!D3:D317) | E5: =COUNTIFS(Позиции!A3:A317,"1.4",Позиции!J3:J317,">0") | F5: =SUMIF(Позиции!A3:A317,"1.4",Позиции!O3:O317)
A6: 1.5 | B6: Спец. №2 · КТЭЦ · ТО | C6: =COUNTIF(Позиции!A3:A317,"1.5") | D6: =SUMIF(Позиции!A3:A317,"1.5",Позиции!D3:D317) | E6: =COUNTIFS(Позиции!A3:A317,"1.5",Позиции!J3:J317,">0") | F6: =SUMIF(Позиции!A3:A317,"1.5",Позиции!O3:O317)
A7: 1.6 | B7: Спец. №3 · Коммунальная энергетика · ремонт | C7: =COUNTIF(Позиции!A3:A317,"1.6") | D7: =SUMIF(Позиции!A3:A317,"1.6",Позиции!D3:D317) | E7: =COUNTIFS(Позиции!A3:A317,"1.6",Позиции!J3:J317,">0") | F7: =SUMIF(Позиции!A3:A317,"1.6",Позиции!O3:O317)
A8: 1.7 | B8: Спец. №3 · Коммунальная энергетика · ТО | C8: =COUNTIF(Позиции!A3:A317,"1.7") | D8: =SUMIF(Позиции!A3:A317,"1.7",Позиции!D3:D317) | E8: =COUNTIFS(Позиции!A3:A317,"1.7",Позиции!J3:J317,">0") | F8: =SUMIF(Позиции!A3:A317,"1.7",Позиции!O3:O317)
A9: 1.8 | B9: Спец. №4 · ЦЭС · ремонт | C9: =COUNTIF(Позиции!A3:A317,"1.8") | D9: =SUMIF(Позиции!A3:A317,"1.8",Позиции!D3:D317) | E9: =COUNTIFS(Позиции!A3:A317,"1.8",Позиции!J3:J317,">0") | F9: =SUMIF(Позиции!A3:A317,"1.8",Позиции!O3:O317)
